Workbook
Name _1L: 'Data Validation'!$C$751
Name _1P: 'Data Validation'!$C$749
Name _2L: 'Data Validation'!$C$752
Name _2P: 'Data Validation'!$C$750
Name _2PL: Breakdown!$BM$12:$BM$1170
Name _Prf1: 'Data Validation'!$D$1087
Name _pxl: Breakdown!$BN$12:$BN$1170
Name _ram1: 'Data Validation'!$D$1181
Name _ram2: 'Data Validation'!$D$1182
Name _rel1: 'Data Validation'!$C$885
Name _rel10: 'Data Validation'!$C$894
Name _rel11: 'Data Validation'!$C$895
Name _rel12: 'Data Validation'!$C$896
Name _rel13: 'Data Validation'!$C$897
Name _rel14: 'Data Validation'!$C$898
Name _rel2: 'Data Validation'!$C$886
Name _rel3: 'Data Validation'!$C$887
Name _rel4: 'Data Validation'!$C$888
Name _rel5: 'Data Validation'!$C$889
Name _rel6: 'Data Validation'!$C$890
Name _rel7: 'Data Validation'!$C$891
Name _rel8: 'Data Validation'!$C$892
Name _rel9: 'Data Validation'!$C$893
Name acrylic_mled: stock!$D$623
Name amfcptr: 'Data Validation'!$D$1188
Name amhcptr: 'Data Validation'!$D$1186
Name amhcptrFlap: 'Data Validation'!$D$1187
Name amled9: 'Data Validation'!$D$1183
Name amwrd: 'Data Validation'!$D$1184
Name amwrddlm: 'Data Validation'!$D$1185
Name anodize: 'Data Validation'!$C$902:$C$909
Name anodizeh: Breakdown!$AR$12:$AR$1170
Name anodizev: Breakdown!$AP$12:$AP$1170
Name anodizev2: Breakdown!$AQ$12:$AQ$1170
Name AR_20: stock!$D$1354:$D$1358
Name ar_52: stock!$D$1395
Name avantech: stock!$D$449:$D$458
Name avantech_dasar: 'Data Validation'!$D$1165
Name avantech_palang: 'Data Validation'!$D$1164
Name aventos: stock!$D$525:$D$530
Name bahan1: 'Data Validation'!$C$386
Name bahan2: 'Data Validation'!$C$387
Name bahan3: 'Data Validation'!$C$388
Name bahan4: 'Data Validation'!$C$389
Name bahan5: 'Data Validation'!$C$390
Name bahan6: 'Data Validation'!$C$391
Name bahan7: 'Data Validation'!$C$392
Name bahan8: 'Data Validation'!$C$393
Name ball_bearing: stock!$D$433:$D$438
Name BARANG: stock!$D$4:$D$2304
Name braket_hc: stock!$D$642
Name breakdown: Breakdown!$A$11:$CF$1170
Name camar_807: stock!$D$640
Name cekbox: stock!$B$2320:$B$2323
Name centrallock_samping: stock!$D$586
Name Cermin: stock!$D$2716:$D$2739
Name cfr: 'Data Validation'!$A$826:$A$841
Name CL_02: stock!$D$1293:$D$1297
Name Cov_plinth_dalam: stock!$D$1105:$D$1118
Name Cov_plinth_luar: stock!$D$1090:$D$1104

Sheet stock
A1: KEBUTUHAN MATERIAL
A3: NO | B3: KATEGORI | C3: ID BARANG | D3: NAMA BARANG | E3: JML | F3: SATUAN | G3: KETERANGAN | I3: Ket
A5: 3 | B5: Ply lantrex Polos | C5: 101079 | D5: Ply LANTREX 3 mm polos untuk pintu | F5: Lbr | G5: Anti Rayap
A6: 6 | B6: Ply lantrex Polos | C6: 101080 | D6: Ply LANTREX 6 mm polos untuk pintu | F6: Lbr | G6: Anti Rayap
A7: 6 | B7: Ply lantrex Polos | C7: 101081 | D7: Ply LANTREX 6 mm polos untuk box | F7: Lbr | G7: Anti Rayap
A8: 6 | B8: Ply lantrex Polos | C8: 101082 | D8: Ply LANTREX 6 mm polos untuk kelengkapan | F8: Lbr | G8: Anti Rayap
A9: 9 | B9: Ply lantrex Polos | C9: 101083 | D9: Ply LANTREX 9 mm polos untuk pintu | F9: Lbr | G9: Anti Rayap
A10: 9 | B10: Ply lantrex Polos | C10: 101084 | D10: Ply LANTREX 9 mm polos untuk box | F10: Lbr | G10: Anti Rayap
A11: 9 | B11: Ply lantrex Polos | C11: 101085 | D11: Ply LANTREX 9 mm polos untuk kelengkapan | F11: Lbr | G11: Anti Rayap
A12: 12 | B12: Ply lantrex Polos | C12: 101086 | D12: Ply LANTREX 12 mm polos untuk pintu | F12: Lbr | G12: Anti Rayap
A13: 12 | B13: Ply lantrex Polos | C13: 101087 | D13: Ply LANTREX 12 mm polos untuk kelengkapan | F13: Lbr | G13: Anti Rayap
A14: 13 | B14: Ply lantrex Polos | C14: 101088 | D14: Ply LANTREX 13 mm polos untuk pintu | F14: Lbr | G14: Anti Rayap
A15: 14.5 | B15: Ply lantrex Polos | C15: 101089 | D15: Ply LANTREX 14.5 mm polos untuk pintu | F15: Lbr | G15: Anti Rayap
A16: 14.5 | B16: Ply lantrex Polos | C16: 101090 | D16: Ply LANTREX 14.5 mm polos untuk box | F16: Lbr | G16: Anti Rayap
... A34: 3 | B34: Ply lantrex Polos u Duco | C34: 101010 | D34: Ply 3 mm LANTREX untuk Duco | F34: Lbr | G34: Anti Rayap
B35: HPL u Duco | C35: 121531 | D35: HPL untuk duco 4X10 | F35: Lbr | G35: Anti Rayap
B36: HPL u Duco | C36: 121533 | D36: HPL untuk duco 4X8 | F36: Lbr | G36: Anti Rayap
B37: HPL | C37: 120125 | D37: HPL Aica 1311 | F37: Lbr
A39: 18 | B39: Ply lantrex Polos | C39: 101099 | D39: Ply LANTREX 18 mm MARINE | F39: Lbr | G39: Anti Rayap
A41: 18 | B41: Ply lantrex aica 2mk | C41: 100848 | D41: Ply LANTREX 18 mm HPL Putih 2 mk | F41: Lbr | G41: Anti Rayap
A42: 9 | B42: Ply lantrex Aica 1mk | C42: 100867 | D42: Ply LANTREX 9 mm HPL Putih 1 mk | F42: Lbr | G42: Anti Rayap
A44: 18 | B44: Ply lantrex aica 2mk | C44: 101025 | D44: Ply LANTREX 18 mm HPL Mocca 1337 A 2 mk | F44: Lbr | G44: Anti Rayap | H44: Edg Rehau 270 B
A45: 18 | B45: Ply lantrex Mocca+Aica | C45: 101026 | D45: Ply LANTREX 18 mm HPL Mocca 1337 A + HPL Putih | F45: Lbr | G45: Anti Rayap | H45: Edg Rehau 270 B
A46: 15 | B46: Ply lantrex Mocca 2mk | C46: 101027 | D46: Ply LANTREX 15 mm HPL Mocca 1337 A 2 mk | F46: Lbr | G46: Anti Rayap | H46: Edg Rehau 270 B
A47: 5.5 | B47: Ply lantrex Mocca+Aica | C47: 100849 | D47: Ply LANTREX 5,5 mm lokal HPL Mocca 1337 A + HPL Putih | F47: Lbr | G47: Anti Rayap | H47: Edg Rehau 270 B
A48: 6 | B48: Ply lantrex Mocca+GS 1 | C48: 100924 | D48: Ply LANTREX 6 mm lokal lapis HPL Mocca 1337 A + HPL GS 1 | F48: Lbr | G48: Anti Rayap | H48: Edg Rehau 270 B
B49: HPL | C49: 120221 | D49: HPL mocha 1337 A 4x8 | F49: Lbr | G49: Anti Rayap | H49: Edg Rehau 270 B
B50: Edging | C50: 210049 | D50: Edg Rehau 270 B uk : 23x1
A52: 18 | B52: Ply lantrex C001 2mk | C52: 100968 | D52: Ply LANTREX 18 mm HPL C 001 LD 2 mk | F52: Lbr | G52: Anti Rayap | H52: Edg Rehau 558
A53: 18 | B53: Ply lantrex C001 + Aica | C53: 100969 | D53: Ply LANTREX 18 mm HPL C 001 LD + HPL Putih | F53: Lbr | G53: Anti Rayap | H53: Edg Rehau 558
A54: 15 | B54: Ply lantrex C001 2mk | C54: 100852 | D54: Ply LANTREX 15 mm HPL C 001 LD 2 mk | F54: Lbr | G54: Anti Rayap | H54: Edg Rehau 558
A55: 6 | B55: Ply lantrex C001 + Aica | C55: 101111 | D55: Ply LANTREX 6 mm HPL C 001 LD + HPL Putih | F55: Lbr | G55: Anti Rayap | H55: Edg Rehau 558
B56: Edging | C56: 210047 | D56: Edg Rehau 558 uk : 23x1
B57: Edging | C57: 210164 | D57: Edg Rehau 558 uk : 29x1
B58: Edging | C58: 220198 | D58: Edg Rehau 558 uk : 55x1.5
A60: 24 | B60: Ply lantrex HB 41130 2mk | C60: 100854 | D60: Ply LANTREX 24 mm HPL HB 41130 2 mk | F60: Lbr | G60: Anti Rayap | H60: Edg Decor 1723 B
A61: 18 | B61: Ply lantrex HB 41130 2mk | C61: 100903 | D61: Ply LANTREX 18 mm HPL HB 41130 2 mk | F61: Lbr | G61: Anti Rayap | H61: Edg Decor 1723 B
A62: 18 | B62: Ply lantrex HB 41130 + Aica | C62: 100904 | D62: Ply LANTREX 18 mm HPL HB 41130 + HPL Putih | F62: Lbr | G62: Anti Rayap | H62: Edg Decor 1723 B
A63: 15 | B63: Ply lantrex HB 41130 2mk | C63: 100855 | D63: Ply LANTREX 15 mm HPL HB 41130 2 mk | F63: Lbr | G63: Anti Rayap | H63: Edg Decor 1723 B
A64: 6 | B64: Ply lantrex HB 41130 + Aica | C64: 100905 | D64: Ply LANTREX 6 mm lapis HPL HB 41130 + HPL putih | F64: Lbr | G64: Anti Rayap | H64: Edg Decor 1723 B
...

Sheet Spek
D1: awali dengan bismillah . . .
B2: tanggal | C2: : | D2: 46163 | E2: Val. | F2: note | G2: KS
B3: No Rekap | C3: : | D3: RZ0458
B4: Estimator | C4: : | D4: Fahrudin
B5: Koordinator Rekap | C5: : | D5: Reza Pahlevi | E5: Reza Pahlevi
B6: Status Proyek
B7: ADA PENDINGAN | C7: :
B8: TIDAK ADA PEND. | C8: : | D8: √
B9: ANTI RAYAP | C9: :
B10: TIDAK ANTIRAYAP | C10: : | D10: √
B11: Form Order
B12: No.Kontrak | C12: : | D12: 127/RK-RL-PI/PAP-LL/XII/2025
B13: NIP | C13: : | D13: 25LL017MPC
B14: Nama Produk | C14: : | D14: Dry Pantry
B15: Nama Proyek | C15: : | D15: PT Malindo Feedmill Tbk | I15: =CONCATENATE((Spek!$D$15),"-",(Spek!$D$14)) -> PT Malindo Feedmill Tbk-Dry Pantry
B16: Spesifikasi Produk
B17: Bahan Kabinet 1 | C17: : | D17: Ply | F17: bahan1 (u/ box)
B18: Bahan Kabinet 2 | C18: : | D18: Ply+mdf hijau 1mk | F18: bahan2
B19: Bahan Kabinet 3 | C19: : | D19: Ply+mdf hijau 2mk | F19: bahan3
B20: Bahan Kabinet 4 | C20: : | D20: Mdf hijau | F20: bahan4
B21: Bahan Kabinet 5 | C21: : | D21: Ply | F21: bahan5 (u/ pintu)
B22: Bahan Kabinet 6 | C22: : | D22: UPVC | F22: bahan6
B23: Bahan Kabinet 7 | C23: : | D23: Ply Bending | F23: bahan7
B24: Bahan Kabinet 8 | C24: : | D24: Blockboard | F24: bahan8
B27: Spesifikasi tebal bahan
B28: Komponen kabinet | C28: : | D28: 18
B29: Komponen laci | C29: : | D29: 12
B30: Dinding blk / dasar | C30: : | D30: 6
B31: Tatakan S/s | C31: : | D31: 18
B32: Tatakan worktop | C32: : | D32: 27
B34: Spesifikasi Lapisan / Fin.
A35: 11 | B35: Lapisan dibalik pintu | C35: : | D35: =IFERROR(INDEX((tf),MATCH(A35,ctf,0)),"") -> HB_41130 | F35: =IF(A35=1,edging1,IF(A35=11,edgingkab1,"cek tipe edging")) -> Edg_Décor_1723_B
A36: 0 | B36: Lapisan tidak terlihat u/ kab. | C36: : | D36: =IFERROR(INDEX((tf),MATCH(A36,ctf,0)),"") -> Polos
A37: 0 | B37: Lapisan depan bhn pintu mlp | C37: : | D37: =IFERROR(INDEX((tf),MATCH(A37,ctf,0)),"") -> Polos
C38: :
B39: tipe edg. u/ sisi tidak terlihat | C39: : | D39: Melanor
B40: tipe lap. u/ sisi tidak terlihat | C40: : | D40: =IF($D$42="AL01","AL01",IF($D$42="MWW_003",lapisan_luar_paper,IF($D$42="MWW_004",lapisan_luar_paper,IF($D$42="MM_002",lapisan_luar_paper,lapisan_luar_hb)))) -> [Aica] | E40: =IF($B$42="paper",(INDEX((tbl_paper),MATCH($D40,paper,0))),(INDEX((tbl_hpl),MATCH($D40,HPL,0)))) -> 0.5
A42: 11 | B42: HPL | C42: : | D42: HB_41130 | E42: =IF(B42="paper",(INDEX((tbl_paper),MATCH($D42,paper,0))),(INDEX((tbl_hpl),MATCH($D42,HPL,0)))) -> 0.5 | F42: kabinet1
B43: Edg | C43: : | D43: Edg_Décor_1723_B | F43: edgingkab1
A44: 22 | B44: HPL | C44: : | D44: Aica | E44: =IF(B44="paper",(INDEX((tbl_paper),MATCH($D44,paper,0))),(INDEX((tbl_hpl),MATCH($D44,HPL,0)))) -> 0.5 | F44: kabinet2
...

Sheet Data Validation
A6: √ | B6: Code | C6: Name | D6: Val | E6: KS | F6: Ket. | G6: OPT | H6: jml sub | I6: Bhn | J6: T | K6: minifix | L6: dowel | O6: tipe siku | P6: tipe screw | Q6: V | R6: V2 | S6: H | T6: profil 3 | U6: profil 2 | V6: profil | W6: L | X6: D | Y6: P1 | Z6: P2 | AA6: L1 | AB6: L2 | AD6: Rel | AE6: Engsel | AF6: Anodize/ | AG6: jumlah anodize @ | AH6: P | AI6: L | AJ6: @siku | AK6: @ screw
B7: Prt | C7: Parts
A8: kabinet | B8: Parts | C8: Dinding Samping | D8: =ROW()+93 -> 101 | E8: KS | G8: 1 | H8: 1 | I8: =bahan1 -> Ply | J8: 18 | W8: =Spek!$A$36 -> 0 | X8: 11 | Y8: 11 | Z8: =IF(Spek!$A$36=0,9,11) -> 9 | AA8: =IF(Spek!$A$36=0,9,11) -> 9 | AB8: =IF(Spek!$A$36=0,9,11) -> 9 | AC8: √
A9: kabinet | B9: Parts | C9: Dinding Samping≈ | D9: =ROW()+93 -> 102 | E9: KS | G9: 1 | H9: 1 | I9: =bahan1 -> Ply | J9: 18 | W9: 11 | X9: 11 | Y9: 11 | Z9: 11 | AA9: 11 | AB9: 11
A10: kabinet | B10: Parts | C10: Dinding Samping• | D10: =ROW()+93 -> 103 | E10: KS | G10: 1 | H10: 1 | I10: =bahan1 -> Ply | J10: 18 | W10: 3 | X10: 11 | Y10: 3 | Z10: 3 | AA10: 3 | AB10: 3
A11: kabinet | B11: Parts | C11: Dinding Samping I | D11: =ROW()+93 -> 104 | E11: KS | G11: 1 | H11: 1 | I11: =bahan1 -> Ply | J11: 18 | W11: 1 | X11: 11 | Y11: 1 | Z11: 1 | AA11: 1 | AB11: 1
A12: kabinet | B12: Parts | C12: Dinding Samping║ | D12: =ROW()+93 -> 105 | E12: KS | G12: 1 | H12: 1 | I12: =bahan1 -> Ply | J12: 18 | W12: 2 | X12: 11 | Y12: 11 | Z12: =IF(Spek!$A$36=0,9,11) -> 9 | AA12: =IF(Spek!$A$36=0,9,11) -> 9 | AB12: =IF(Spek!$A$36=0,9,11) -> 9 | AC12: √
A13: kabinet | B13: Parts | C13: Dinding Samping« | D13: =ROW()+93 -> 106 | E13: KS | G13: 1 | H13: 1 | I13: =bahan1 -> Ply | J13: 18 | W13: 4 | X13: 11 | Y13: 11 | Z13: =IF(Spek!$A$36=0,9,11) -> 9 | AA13: =IF(Spek!$A$36=0,9,11) -> 9 | AB13: =IF(Spek!$A$36=0,9,11) -> 9 | AC13: √
A14: kabinet | B14: Parts | C14: Dinding Samping OS | D14: =ROW()+93 -> 107 | E14: KS | G14: 0 | H14: 1 | I14: =bahan1 -> Ply | J14: 18 | W14: =IF(Spek!$B$42="paper",22,Spek!$A$36) -> 0 | X14: 1 | Y14: 1 | Z14: 1 | AA14: 1 | AB14: 1
A15: kabinet | B15: Parts | C15: Dinding Samping OS I | D15: =ROW()+93 -> 108 | E15: KS | G15: 0 | H15: 1 | I15: =bahan1 -> Ply | J15: 18 | W15: 1 | X15: 1 | Y15: 1 | Z15: 1 | AA15: 1 | AB15: 1
A16: kabinet | B16: Parts | C16: Dinding Samping OS║ | D16: =ROW()+93 -> 109 | E16: KS | G16: 0 | H16: 1 | I16: =bahan1 -> Ply | J16: 18 | W16: 2 | X16: 1 | Y16: 1 | Z16: 1 | AA16: 1 | AB16: 1
A17: kabinet | B17: Parts | C17: Dinding Samping OS• | D17: =ROW()+93 -> 110 | E17: KS | G17: 0 | H17: 1 | I17: =bahan1 -> Ply | J17: 18 | W17: =IF(Spek!$B$42="paper",22,Spek!$A$36) -> 0 | X17: 3 | Y17: 3 | Z17: 3 | AA17: 3 | AB17: 3
A18: kabinet | B18: Parts | C18: Dinding Samping OS•• | D18: =ROW()+93 -> 111 | E18: KS | G18: 0 | H18: 1 | I18: =bahan1 -> Ply | J18: 18 | W18: 3 | X18: 3 | Y18: 3 | Z18: 3 | AA18: 3 | AB18: 3
A19: kabinet | B19: Parts | C19: Dinding Samping Kaca | D19: =ROW()+93 -> 112 | E19: KS | G19: 1 | H19: 1 | I19: =bahan1 -> Ply | J19: 13.5 | W19: 22 | X19: 11 | Y19: 11 | Z19: 11 | AA19: 11 | AB19: 11
A20: kabinet | B20: Parts | C20: Dinding Samping Kaca S2 | D20: =ROW()+93 -> 113 | E20: KS | G20: 1 | H20: 1 | I20: =bahan1 -> Ply | J20: 13.5 | W20: 22 | X20: 11 | Y20: 1 | Z20: 1 | AA20: 0 | AB20: 0 | AF20: =IF(Spek!$D$17="UPVC",edging7,edging8) -> Trim 22 S2/S4 Brown Doff ( Alm. 75270 ) P3 | AG20: 2
A21: kabinet | B21: Parts | C21: Dinding Samping Kaca S4 | D21: =ROW()+93 -> 114 | E21: KS | G21: 1 | H21: 1 | I21: =bahan1 -> Ply | J21: 13.5 | W21: 22 | X21: 11 | Y21: 8 | Z21: 8 | AA21: 8 | AB21: 8
A22: kabinet | B22: Parts | C22: Samping WIC | D22: =ROW()+93 -> 115 | E22: KS | G22: 1 | H22: 2 | I22: =bahan1 -> Ply | J22: 24 | K22: =minifix_hettich -> MINIFIX HETTICH | L22: =dowelØ8 -> DOWEL KAYU 4X8 | W22: 11 | X22: 11 | Y22: 22 | Z22: 0 | AA22: 22 | AB22: 22
A23: kabinet | B23: Parts | C23: Komp. OS Manual | D23: =ROW()+93 -> 116 | E23: KS | G23: 1 | H23: 1 | I23: =bahan1 -> Ply
A24: kabinet | B24: Parts | C24: Dinding Atas Bawah ↓ | D24: =ROW()+93 -> 117 | E24: KS | G24: 1 | H24: 1 | I24: =bahan1 -> Ply | J24: 18 | K24: =minifix_hettich -> MINIFIX HETTICH | L24: =dowelØ8 -> DOWEL KAYU 4X8 | T24: =legadj100 -> KAKI ADJUSTER HAFELLE TG 100 ART # 637.45.326 | W24: =Spek!$A$36 -> 0 | X24: 11 | Y24: 11 | Z24: =IF(Spek!$A$36=0,9,11) -> 9 | AA24: 0 | AB24: 0 | AC24: √
A25: kabinet | B25: Parts | C25: Dinding Atas Bawah ↑ | D25: =ROW()+93 -> 118 | E25: KS | G25: 1 | H25: 1 | I25: =bahan1 -> Ply | J25: 18 | K25: =minifix_hettich -> MINIFIX HETTICH | L25: =dowelØ8 -> DOWEL KAYU 4X8 | T25: =braket_hc -> Braket Kabinet Atas | W25: =Spek!$A$36 -> 0 | X25: 11 | Y25: 11 | Z25: =IF(Spek!$A$36=0,9,11) -> 9 | AA25: 0 | AB25: 0 | AC25: √
A26: kabinet | B26: Parts | C26: Dinding Atas Bawah | D26: =ROW()+93 -> 119 | E26: KS | G26: 1 | H26: 1 | I26: =bahan1 -> Ply | J26: 18 | K26: =minifix_hettich -> MINIFIX HETTICH | L26: =dowelØ8 -> DOWEL KAYU 4X8 | W26: 9 | X26: 11 | Y26: 11 | Z26: =IF(Spek!$A$36=0,9,11) -> 9 | AA26: 0 | AB26: 0 | AC26: √
A27: kabinet | B27: Parts | C27: Dinding Atas Bawah• | D27: =ROW()+93 -> 120 | E27: KS | G27: 1 | H27: 1 | I27: =bahan1 -> Ply | J27: 18 | K27: =minifix_hettich -> MINIFIX HETTICH | L27: =dowelØ8 -> DOWEL KAYU 4X8 | W27: 3 | X27: 11 | Y27: 3 | Z27: 3 | AA27: 0 | AB27: 0
A28: kabinet | B28: Parts | C28: Dinding Atas Bawah I | D28: =ROW()+93 -> 121 | E28: KS | G28: 1 | H28: 1 | I28: =bahan1 -> Ply | J28: 18 | K28: =minifix_hettich -> MINIFIX HETTICH | L28: =dowelØ8 -> DOWEL KAYU 4X8 | W28: 1 | X28: 11 | Y28: 11 | Z28: 11 | AA28: 0 | AB28: 0
A29: kabinet | B29: Parts | C29: Dinding Atas Bawah ≈ | D29: =ROW()+93 -> 122 | E29: KS | G29: 1 | H29: 1 | I29: =bahan1 -> Ply | J29: 18 | K29: =minifix_hettich -> MINIFIX HETTICH | L29: =dowelØ8 -> DOWEL KAYU 4X8 | W29: 11 | X29: 11 | Y29: 11 | Z29: =IF(Spek!$A$36=0,9,11) -> 9 | AA29: 0 | AB29: 0 | AC29: √
A30: kabinet | B30: Parts | C30: Dinding Atas Bawah ∟↓ | D30: =ROW()+93 -> 123 | E30: KS | G30: 1 | H30: 1 | I30: =bahan1 -> Ply | J30: 18 | K30: =minifix_hettich -> MINIFIX HETTICH | L30: =dowelØ8 -> DOWEL KAYU 4X8 | W30: =Spek!$A$36 -> 0 | X30: 11 | Y30: 0 | Z30: =IF(Spek!$A$36=0,9,11) -> 9 | AA30: 0 | AB30: =IF(Spek!$A$36=0,9,11) -> 9 | AC30: √
A31: kabinet | B31: Parts | C31: Dinding Atas Bawah ∟ | D31: =ROW()+93 -> 124 | E31: KS | G31: 1 | H31: 1 | I31: =bahan1 -> Ply | J31: 18 | K31: =minifix_hettich -> MINIFIX HETTICH | L31: =dowelØ8 -> DOWEL KAYU 4X8 | W31: 9 | X31: 11 | Y31: 0 | Z31: =IF(Spek!$A$36=0,9,11) -> 9 | AA31: 0 | AB31: =IF(Spek!$A$36=0,9,11) -> 9 | AC31: √
A32: kabinet | B32: Parts | C32: Dinding Atas Bawah I | D32: =ROW()+93 -> 125 | E32: KS | G32: 1 | H32: 1 | I32: =bahan1 -> Ply | J32: 18 | K32: =minifix_hettich -> MINIFIX HETTICH | L32: =dowelØ8 -> DOWEL KAYU 4X8 | W32: 1 | X32: 11 | Y32: 11 | Z32: 11 | AA32: 0 | AB32: 0
A33: kabinet | B33: Parts | C33: Dinding Atas Bawah OS↓ | D33: =ROW()+93 -> 126 | E33: KS | G33: 0 | H33: 1 | I33: =bahan1 -> Ply | J33: 18 | K33: =minifix_hettich -> MINIFIX HETTICH | L33: =dowelØ8 -> DOWEL KAYU 4X8 | W33: 0 | X33: 1 | Y33: 1 | Z33: 1 | AA33: 0 | AB33: 0
A34: kabinet | B34: Parts | C34: Dinding Atas Bawah OS | D34: =ROW()+93 -> 127 | E34: KS | G34: 0 | H34: 1 | I34: =bahan1 -> Ply | J34: 18 | K34: =minifix_hettich -> MINIFIX HETTICH | L34: =dowelØ8 -> DOWEL KAYU 4X8 | W34: 22 | X34: 1 | Y34: 1 | Z34: 1 | AA34: 0 | AB34: 0
A35: kabinet | B35: Parts | C35: Dinding Atas Bawah OS│ | D35: =ROW()+93 -> 128 | E35: KS | G35: 0 | H35: 1 | I35: =bahan1 -> Ply | J35: 18 | K35: =minifix_hettich -> MINIFIX HETTICH | L35: =dowelØ8 -> DOWEL KAYU 4X8 | W35: 1 | X35: 1 | Y35: 1 | Z35: 1 | AA35: 0 | AB35: 0
A36: kabinet | B36: Parts | C36: Dinding Atas Bawah OS║ | D36: =ROW()+93 -> 129 | E36: KS | G36: 0 | H36: 1 | I36: =bahan1 -> Ply | J36: 18 | K36: =minifix_hettich -> MINIFIX HETTICH | L36: =dowelØ8 -> DOWEL KAYU 4X8 | W36: 1 | X36: 2 | Y36: 1 | Z36: 1 | AA36: 0 | AB36: 0
A37: kabinet | B37: Parts | C37: Dinding Atas Bawah OS• | D37: =ROW()+93 -> 130 | E37: KS | G37: 0 | H37: 1 | I37: =bahan1 -> Ply | J37: 18 | K37: =minifix_hettich -> MINIFIX HETTICH | L37: =dowelØ8 -> DOWEL KAYU 4X8 | W37: 22 | X37: 3 | Y37: 3 | Z37: 3 | AA37: 0 | AB37: 0
A38: kabinet | B38: Parts | C38: Dinding Atas Bawah OS•• | D38: =ROW()+93 -> 131 | E38: KS | G38: 0 | H38: 1 | I38: =bahan1 -> Ply | J38: 18 | K38: =minifix_hettich -> MINIFIX HETTICH | L38: =dowelØ8 -> DOWEL KAYU 4X8 | W38: 3 | X38: 3 | Y38: 3 | Z38: 3 | AA38: 0 | AB38: 0
A39: kabinet | B39: Parts | C39: Dinding Atas Bawah OS ∟ | D39: =ROW()+93 -> 132 | E39: KS | G39: 0 | H39: 1 | I39: =bahan1 -> Ply | J39: 18 | K39: =minifix_hettich -> MINIFIX HETTICH | L39: =dowelØ8 -> DOWEL KAYU 4X8 | W39: 22 | X39: 1 | Y39: 0 | Z39: 1 | AA39: 0 | AB39: 1
A40: kabinet | B40: Parts | C40: Dinding Atas WIC | D40: =ROW()+93 -> 133 | E40: KS | G40: 1 | H40: 1 | I40: =bahan1 -> Ply | J40: 18 | K40: =minifix_hettich -> MINIFIX HETTICH | L40: =dowelØ8 -> DOWEL KAYU 4X8 | W40: 11 | X40: 11 | Y40: 11 | Z40: 0 | AA40: 11 | AB40: 0
A41: kabinet | B41: Parts | C41: Palangan | D41: =ROW()+93 -> 134 | E41: KS | G41: 1 | H41: 2 | I41: =bahan1 -> Ply | J41: 18 | K41: =minifix_hettich -> MINIFIX HETTICH | L41: =dowelØ8 -> DOWEL KAYU 4X8 | W41: 9 | X41: 11 | Y41: 11 | Z41: =IF(Spek!$A$36=0,9,11) -> 9 | AA41: 0 | AB41: 0 | AC41: √
A42: kabinet | B42: Parts | C42: Palangan tengah | D42: =ROW()+93 -> 135 | E42: KS | G42: 1 | H42: 1 | I42: =bahan1 -> Ply | J42: 18 | K42: =minifix_hettich -> MINIFIX HETTICH | L42: =dowelØ8 -> DOWEL KAYU 4X8 | W42: 11 | X42: 11 | Y42: 11 | Z42: =IF(Spek!$A$36=0,9,11) -> 9 | AA42: 0 | AB42: 0 | AC42: √
A43: kabinet | B43: Parts | C43: Cover Box Samping | D43: =ROW()+93 -> 136 | E43: KS | G43: 0 | H43: 1 | I43: =bahan1 -> Ply | J43: 18 | K43: =minifix_hettich -> MINIFIX HETTICH | L43: =dowelØ8 -> DOWEL KAYU 4X8 | W43: 1 | X43: 1 | Y43: 1 | Z43: 1 | AA43: 1 | AB43: 0
A44: kabinet | B44: Parts | C44: Cover Box Atas | D44: =ROW()+93 -> 137 | E44: KS | G44: 0 | H44: 1 | I44: =bahan1 -> Ply | J44: 18 | W44: 1 | X44: 22 | Y44: 1 | Z44: 1 | AA44: 1 | AB44: 1
A45: kabinet | B45: Parts | C45: Cover Box Bawah | D45: =ROW()+93 -> 138 | E45: KS | G45: 0 | H45: 1 | I45: =bahan1 -> Ply | J45: 18 | K45: =minifix_hettich -> MINIFIX HETTICH | L45: =dowelØ8 -> DOWEL KAYU 4X8 | W45: 22 | X45: 1 | Y45: 1 | Z45: 1 | AA45: 0 | AB45: 0
...

Sheet Breakdown
AP9: Bon Anodize
R10: Material | T10: Lapisan | Y10: Edging | AP10: batangan | AS10: per ukuran
A11: id | B11: cat. | C11: type | D11: kode | E11: Tpk | F11: Opt | G11: No | H11: Komponen | I11: Proses Khusus | J11: P | K11: x | L11: L | M11: x | N11: T | O11: Ukuran | P11: Sub | Q11: Jml | R11: Bahan | S11: T Bahan | T11: L | U11: D | V11: Luar | W11: T | X11: Dalam | Y11: T | Z11: P1 | AA11: P2 | AB11: L1 | AC11: L2 | AD11: P1 | AE11: P2 | AF11: L1 | AG11: L2 | AH11: Profil 3 | AI11: Profil 2 | AJ11: Profil | AK11: Siku joint | AL11: Screw Jf | AM11: Door mec | AN11: Rel | AO11: Engsel | AP11: V | AQ11: V2 | AR11: H | AS11: Nama barang | AT11: Panjang | AU11: Jumlah | AV11: x | AW11: V lap | AX11: V edg | AY11: Deskripsi lapisan | AZ11: Deskripsi edging | BA11: Deskripsi Komponen | BB11: Nama Komponen | BC11: x | BD11: Minifix | BE11: Dowel | BF11: @siku | BG11: @ screw | BH11: Dormec | BI11: Engsel | BJ11: Rel | BK11: P | BL11: L | BM11: 2(P+L) | BN11: (PxL) | BO11: Bahan Dasar | BP11: Deskripsi Bahan | BQ11: /panel | BR11: jumlah anodize @ | BS11: minifix @ | BT11: dowel @ | BU11: jml siku | BV11: jml screw | BW11: M² | BX11: M³ | BY11: T_P1 | BZ11: T_P2 | CA11: T_L1 | CB11: T_L2 | CC11: P_cnc | CD11: L_cnc | CE11: ukuran CNC | CF11: CSV Format
BY12: =IFERROR(INDEX((tbl_edg),MATCH($AD12,Edg,0)),"") | BZ12: =IFERROR(INDEX((tbl_edg),MATCH($AE12,Edg,0)),"") | CA12: =IFERROR(INDEX((tbl_edg),MATCH($AF12,Edg,0)),"") | CB12: =IFERROR(INDEX((tbl_edg),MATCH($AG12,Edg,0)),"")
A14: =IFERROR(INDEX((ID),MATCH(H14,BARANG,0)),"…") -> … | B14: =IFERROR(INDEX((cprt),MATCH($H14,Prt,0)),"…") -> … | C14: Set_up | D14: =(INDEX(KS_Set,MATCH($H14,Set_prt,0))) -> [ks] | E14: A | F14: =IFERROR(INDEX((opt),MATCH($H14,Prt,0)),"") | G14: =IFERROR(INDEX((no_ref),MATCH($H14,ref,0)),"...") -> • | H14: Back Panel Rangka (rakit tukang) | J14: 2000 | K14: x | L14: 209 | M14: x | N14: 75 | O14: =CONCATENATE(J14," ",K14," ",L14," ",M14," ",N14) -> 2000 x 209 x 75 | Q14: 1 | AD14: =IF($B14="alu",(INDEX((Fr),MATCH(Z14,cfr,0))),INDEX((te),MATCH(Z14,cte,0))) | AE14: =IF($B14="alu",(INDEX((Fr),MATCH(AA14,cfr,0))),INDEX((te),MATCH(AA14,cte,0))) | AF14: =IF($B14="alu",(INDEX((Fr),MATCH(AB14,cfr,0))),INDEX((te),MATCH(AB14,cte,0))) | AG14: =IF($B14="alu",(INDEX((Fr),MATCH(AC14,cfr,0))),INDEX((te),MATCH(AC14,cte,0))) | AK14: =IFERROR(INDEX((std_siku_prt),MATCH($H14,Prt,0)),"") | AL14: =IFERROR(INDEX((std_screw_prt),MATCH($H14,Prt,0)),"") | AP14: =IFERROR(INDEX((std_anodizev_proses),MATCH($I14,pk,0)),"") | AQ14: =IFERROR(INDEX((std_anodizev2_proses),MATCH($I14,pk,0)),"") | AR14: =IFERROR(INDEX((std_anodizeh_proses),MATCH($I14,pk,0)),"") | AU14: =IF($AS14=0,"",Q14*BR14) | AX14: =IF($B14="alu",(CONCATENATE(VLOOKUP($AD14,tabfr,2,0),VLOOKUP($AE14,tabfr,2,0),VLOOKUP($AF14,tabfr,2,0),VLOOKUP($AG14,tabfr,2,0))),(CONCATENATE(VLOOKUP($AD14,tabte,2,0),VLOOKUP($AE14,tabte,2,0),VLOOKUP($AF14,tabte,2,0),VLOOKUP($AG14,tabte,2,0)))) -> 3333 | AY14: =IFERROR(VLOOKUP(AW14,descf,2,0),"") | AZ14: =IF($B14="alu",(VLOOKUP(AX14,descfr,2,0)),(VLOOKUP(AX14,desce,2,0))) -> - | BA14: =IF($R14=0,CONCATENATE(0,")"," ",$H14," ",$J14),CONCATENATE(VLOOKUP(H14,tabprt,2,0),")",$H14,"_",AY14)) -> 0) Back Panel Rangka (rakit tukang) 2000 | BB14: =IF($B14="…",CONCATENATE(0,$E14,")"," ",$H14),IF($B14="kc",CONCATENATE(VLOOKUP(H14,tabprt,2,0),")",$H14," ",$R14," ",$S14,"mm"," ","-"," "," ",";"," ",$AZ14," ",$I14),IF($B14="alu",CONCATENATE(VLOOKUP(H14,tabprt,2,0),")",$H14," ",$R14," ",$S14,"mm"," ","-"," "," ",";"," ",$AZ14," ",$I14),CONCATENATE(VLOOKUP(H14,tabprt,2,0),")",$H14," ",$R14," ",$S14,"mm"," ","-"," ",$AY14," ",";"," ",$AZ14," ",$I14)))) -> 0A) Back Panel Rangka (rakit tukang) | BD14: =IFERROR(INDEX((std_minifix_prt),MATCH($H14,Prt,0)),"") | BE14: =IFERROR(INDEX((std_dowel_prt),MATCH($H14,Prt,0)),"") | BH14: =IF($AM14=0,0,1)*Q14 -> 0 | BI14: =IF($AO14=0,0,IF(J14<=fp,2,(ROUNDUP(J14/fp,0))))*Q14 -> 0 | BJ14: =IF($AN14=0,0,1)*Q14 -> 0 | BK14: =(($J14+tol_p)*$Q14)/1000 -> 2.04 | BL14: =(($L14+tol_p)*$Q14)/1000 -> 0.249 | BM14: =IF(R14=0,0,((2*((J14+tol_p)+(L14+tol_p))*Q14)/1000)) -> 0 | BO14: =CONCATENATE(R14,"_",S14) -> _ | BP14: =CONCATENATE(R14," ",S14," ",AY14) | BQ14: =((J14*L14*Q14)/(2400*1200))+10% -> 0.24513889 | BR14: =IFERROR(INDEX((std_jml_anodize_per_uk),MATCH($H14,Prt,0)),"") | BS14: =IF($BD14=0,0,IF($L14<150,2,((ROUNDUP($L14/fm,0)*2))))*$Q14 -> 2 | BT14: =IF($BE14=0,0,IF($L14<150,2,((ROUNDUP($L14/fd,0)*2))))*$Q14 -> 4 | BW14: =+((J14*L14)*Q14)/1000000 -> 0.418 | BX14: =+((J14*L14*N14)*Q14)/1000000000 -> 0.03135 | BY14: =IFERROR(INDEX((tbl_edg),MATCH($AD14,Edg,0)),"") | BZ14: =IFERROR(INDEX((tbl_edg),MATCH($AE14,Edg,0)),"") | CA14: =IFERROR(INDEX((tbl_edg),MATCH($AF14,Edg,0)),"") | CB14: =IFERROR(INDEX((tbl_edg),MATCH($AG14,Edg,0)),"") | CC14: =IFERROR((J14-CA14-CB14),"") | CD14: =IFERROR((L14-BY14-BZ14),"") | CE14: =IFERROR((CONCATENATE(CC14," ","x"," ",CD14," ","x"," ",N14)),"") -> x x 75 | CF14: =IF(F14=1,(CONCATENATE(J14,";",L14,";",Q14,";",BP14,";",N14,";",H14,";","-1",";",AF14,";",CA14,";",AG14,";",CB14,";",AD14,";",BY14,";",AE14,";",BZ14))," ")
A15: =IFERROR(INDEX((ID),MATCH(H15,BARANG,0)),"…") -> … | B15: =IFERROR(INDEX((cprt),MATCH($H15,Prt,0)),"…") -> pintu | C15: prt | D15: =IFERROR(INDEX((KS),MATCH($H15,Prt,0)),"") -> KS | E15: A» | F15: =IFERROR(INDEX((opt),MATCH($H15,Prt,0)),"") -> 0 | G15: =IFERROR(INDEX((no_ref),MATCH($H15,ref,0)),"...") -> ... | H15: Back Panel Rangka | J15: =+J14 -> 2000 | K15: x | L15: =+L14 -> 209 | M15: x | N15: =+(S15+W15+Y15) -> 19 | O15: =CONCATENATE(J15," ",K15," ",L15," ",M15," ",N15) -> 2000 x 209 x 19 | P15: =IFERROR(INDEX((std_sub_prt),MATCH($H15,Prt,0)),"") -> 1 | Q15: =P15*Q14 -> 1 | R15: =IFERROR(INDEX((std_bhn_prt),MATCH($H15,Prt,0)),"") -> Ply | S15: =IFERROR(INDEX((std_Tbahan_prt),MATCH($H15,Prt,0)),"") -> 18 | T15: =INDEX((std_lapisan_luar_prt),MATCH($H15,Prt,0)) -> 1 | U15: =INDEX((std_lapisan_dalam_prt),MATCH($H15,Prt,0)) -> 0 | V15: =IFERROR(INDEX((tf),MATCH(T15,ctf,0)),"") -> WY_5216_D(V) | W15: =IFERROR(INDEX((tebal_lapisan),MATCH($V15,tf,0)),"") -> 1 | X15: =IFERROR(INDEX((tf),MATCH(U15,ctf,0)),"") -> Polos | Y15: =IFERROR(INDEX((tebal_lapisan),MATCH($X15,tf,0)),"") -> 0 | Z15: =INDEX((std_edg_P1_prt),MATCH($H15,Prt,0)) -> 1 | AA15: =INDEX((std_edg_P2_prt),MATCH($H15,Prt,0)) -> 1 | AB15: =INDEX((std_edg_L1_prt),MATCH($H15,Prt,0)) -> 1 | AC15: =INDEX((std_edg_L2_prt),MATCH($H15,Prt,0)) -> 1 | AD15: =IF($B15="alu",(INDEX((Fr),MATCH(Z15,cfr,0))),INDEX((te),MATCH(Z15,cte,0))) -> Edg_EAW_5216D1 | AE15: =IF($B15="alu",(INDEX((Fr),MATCH(AA15,cfr,0))),INDEX((te),MATCH(AA15,cte,0))) -> Edg_EAW_5216D1 | AF15: =IF($B15="alu",(INDEX((Fr),MATCH(AB15,cfr,0))),INDEX((te),MATCH(AB15,cte,0))) -> Edg_EAW_5216D1 | AG15: =IF($B15="alu",(INDEX((Fr),MATCH(AC15,cfr,0))),INDEX((te),MATCH(AC15,cte,0))) -> Edg_EAW_5216D1 | AH15: =IFERROR(INDEX((std_profil3_prt),MATCH($H15,Prt,0)),"") -> 0 | AI15: =IFERROR(INDEX((std_profil2_prt),MATCH($H15,Prt,0)),"") -> 0 | AJ15: =IFERROR(INDEX((std_profil_prt),MATCH($H15,Prt,0)),"") -> 0 | AK15: =IFERROR(INDEX((std_siku_prt),MATCH($H15,Prt,0)),"") -> 0 | AL15: =IFERROR(INDEX((std_screw_prt),MATCH($H15,Prt,0)),"") -> 0 | AN15: =IFERROR(INDEX((std_rel_prt),MATCH($H15,Prt,0)),"") -> 0 | AO15: =IFERROR(INDEX((std_engsel_prt),MATCH($H15,Prt,0)),"") -> 0 | AP15: =IFERROR(INDEX((std_anodizev_proses),MATCH($I15,pk,0)),"") | AQ15: =IFERROR(INDEX((std_anodizev2_proses),MATCH($I15,pk,0)),"") | AR15: =IFERROR(INDEX((std_anodizeh_proses),MATCH($I15,pk,0)),"") | AS15: =IFERROR(INDEX((std_anodize_per_ukuran),MATCH($H15,Prt,0)),"") -> 0 | AT15: =IF($AS15=edging7,L15,IF($AS15=edging8,L15,IF($AS15=edging9,L15,IF($AS15=Hand1,J14,IF($AS15=Hand2,L14,IF($AS15=hand3,"diisi manual",IF($AS15=hand4,"diisi manual",IF($AS15=hand5,"diisi manual",IF($AS15=mled02,J15,IF($AS15=mprf1,J15,IF($AS15=mlis1,J15,""))))))))))) | AU15: =IF($AS15="","",Q15*BR15) -> 0 | AW15: =CONCATENATE(VLOOKUP($V15,tabtf,2,0),VLOOKUP($X15,tabtf,2,0)) -> 13 | AX15: =IF($B15="alu",(CONCATENATE(VLOOKUP($AD15,tabfr,2,0),VLOOKUP($AE15,tabfr,2,0),VLOOKUP($AF15,tabfr,2,0),VLOOKUP($AG15,tabfr,2,0))),(CONCATENATE(VLOOKUP($AD15,tabte,2,0),VLOOKUP($AE15,tabte,2,0),VLOOKUP($AF15,tabte,2,0),VLOOKUP($AG15,tabte,2,0)))) -> 4444 | AY15: =IFERROR(VLOOKUP(AW15,descf,2,0),"") -> WY_5216_D(V)_1mk_Polos | AZ15: =IF($B15="alu",(VLOOKUP(AX15,descfr,2,0)),(VLOOKUP(AX15,desce,2,0))) -> Edg_EAW_5216D1_Keliling | BA15: =IF($R15=0,CONCATENATE(0,")"," ",$H15," ",$J15),CONCATENATE(VLOOKUP(H15,tabprt,2,0),")",$H15,"_",AY15)) -> 403)Back Panel Rangka_WY_5216_D(V)_1mk_Polos | BB15: =IF($B15="…",CONCATENATE(0,$E15,")"," ",$H15),IF($B15="kc",CONCATENATE(VLOOKUP(H15,tabprt,2,0),")",$H15," ",$R15," ",$S15,"mm"," ","-"," "," ",";"," ",$AZ15," ",$I15),IF($B15="alu",CONCATENATE(VLOOKUP(H15,tabprt,2,0),")",$H15," ",$R15," ",$S15,"mm"," ","-"," "," ",";"," ",$AZ15," ",$I15),CONCATENATE(VLOOKUP(H15,tabprt,2,0),")",$H15," ",$R15," ",$S15,"mm"," ","-"," ",$AY15," ",";"," ",$AZ15," ",$I15)))) -> 403)Back Panel Rangka Ply 18mm - WY_5216_D(V)_1mk_Polos ; Edg_EAW_5216D1_Keliling | BD15: =IFERROR(INDEX((std_minifix_prt),MATCH($H15,Prt,0)),"") -> 0 | BE15: =IFERROR(INDEX((std_dowel_prt),MATCH($H15,Prt,0)),"") -> 0 | BF15: =IFERROR(INDEX((std_j_sikufr_prt),MATCH($H15,Prt,0)),"")*Q15 -> 0 | BG15: =IFERROR(INDEX((std_j_screwjf_prt),MATCH($H15,Prt,0)),"")*Q15 -> 0 | BH15: =IF($AM15=0,0,1)*Q15 -> 0 | BI15: =IF($AO15=0,0,IF(J15<=fp,2,(ROUNDUP(J15/fp,0))))*Q15 -> 0 | BJ15: =IF($AN15=0,0,1)*Q15 -> 0 | BK15: =(($J15+tol_p)*$Q15)/1000 -> 2.04 | BL15: =(($L15+tol_p)*$Q15)/1000 -> 0.249 | BM15: =IF(R15=0,0,((2*((J15+tol_p)+(L15+tol_p))*Q15)/1000)) -> 4.578 | BN15: =((J15*L15)/1000000)*Q15 -> 0.418 | BO15: =CONCATENATE(R15,"_",S15) -> Ply_18 | BP15: =CONCATENATE(R15," ",S15," ",AY15) -> Ply 18 WY_5216_D(V)_1mk_Polos | BQ15: =((J15*L15*Q15)/(2400*1200))+10% -> 0.24513889 | BR15: =IFERROR(INDEX((std_jml_anodize_per_uk),MATCH($H15,Prt,0)),"") -> 0 | BS15: =IF($BD15=0,0,IF($L15<150,2,((ROUNDUP($L15/fm,0)*2))))*$Q15 -> 0 | BT15: =IF($BE15=0,0,IF($L15<150,2,((ROUNDUP($L15/fd,0)*2))))*$Q15 -> 0 | BU15: =BF15*$Q15 -> 0 | BV15: =BG15*$Q15 -> 0 | BW15: =+((J15*L15)*Q15)/1000000 -> 0.418 | BX15: =+((J15*L15*N15)*Q15)/1000000000 -> 0.007942 | BY15: =IFERROR(INDEX((tbl_edg),MATCH($AD15,Edg,0)),"") | BZ15: =IFERROR(INDEX((tbl_edg),MATCH($AE15,Edg,0)),"") | CA15: =IFERROR(INDEX((tbl_edg),MATCH($AF15,Edg,0)),"") | CB15: =IFERROR(INDEX((tbl_edg),MATCH($AG15,Edg,0)),"") | CC15: =IFERROR((J15-CA15-CB15),"") | CD15: =IFERROR((L15-BY15-BZ15),"") | CE15: =IFERROR((CONCATENATE(CC15," ","x"," ",CD15," ","x"," ",N15)),"") -> x x 19 | CF15: =IF(F15=1,(CONCATENATE(J15,";",L15,";",Q15,";",BP15,";",N15,";",H15,";","-1",";",AF15,";",CA15,";",AG15,";",CB15,";",AD15,";",BY15,";",AE15,";",BZ15))," ")
A16: =IFERROR(INDEX((ID),MATCH(H16,BARANG,0)),"…") -> … | B16: =IFERROR(INDEX((cprt),MATCH($H16,Prt,0)),"…") -> pintu | C16: prt | D16: =IFERROR(INDEX((KS),MATCH($H16,Prt,0)),"") -> KS | E16: A | F16: =IFERROR(INDEX((opt),MATCH($H16,Prt,0)),"") -> 1 | G16: =IFERROR(INDEX((no_ref),MATCH($H16,ref,0)),"...") -> ... | H16: Rangka back panel | J16: 2430 | K16: x | L16: =ROUNDDOWN(N14-N15-tol,0) -> 55 | M16: x | N16: =+(S16+W16+Y16) -> 18.5 | O16: =CONCATENATE(J16," ",K16," ",L16," ",M16," ",N16) -> 2430 x 55 x 18,5 | P16: =ROUNDUP((((2*J14)+(4*L14))/2440),0) -> 2 | Q16: =+P16*Q14 -> 2 | R16: =IFERROR(INDEX((std_bhn_prt),MATCH($H16,Prt,0)),"") -> Ply | S16: =IFERROR(INDEX((std_Tbahan_prt),MATCH($H16,Prt,0)),"") -> 18 | T16: =INDEX((std_lapisan_luar_prt),MATCH($H16,Prt,0)) -> 0 | U16: =INDEX((std_lapisan_dalam_prt),MATCH($H16,Prt,0)) -> 22 | V16: =IFERROR(INDEX((tf),MATCH(T16,ctf,0)),"") -> Polos | W16: =IFERROR(INDEX((tebal_lapisan),MATCH($V16,tf,0)),"") -> 0 | X16: =IFERROR(INDEX((tf),MATCH(U16,ctf,0)),"") -> Aica | Y16: =IFERROR(INDEX((tebal_lapisan),MATCH($X16,tf,0)),"") -> 0.5 | Z16: =INDEX((std_edg_P1_prt),MATCH($H16,Prt,0)) -> 0 | AA16: =INDEX((std_edg_P2_prt),MATCH($H16,Prt,0)) -> 9 | AB16: =INDEX((std_edg_L1_prt),MATCH($H16,Prt,0)) -> 0 | AC16: =INDEX((std_edg_L2_prt),MATCH($H16,Prt,0)) -> 0 | AD16: =IF($B16="alu",(INDEX((Fr),MATCH(Z16,cfr,0))),INDEX((te),MATCH(Z16,cte,0))) | AE16: =IF($B16="alu",(INDEX((Fr),MATCH(AA16,cfr,0))),INDEX((te),MATCH(AA16,cte,0))) -> Melanor | AF16: =IF($B16="alu",(INDEX((Fr),MATCH(AB16,cfr,0))),INDEX((te),MATCH(AB16,cte,0))) | AG16: =IF($B16="alu",(INDEX((Fr),MATCH(AC16,cfr,0))),INDEX((te),MATCH(AC16,cte,0))) | AH16: =IFERROR(INDEX((std_profil3_prt),MATCH($H16,Prt,0)),"") -> 0 | AI16: =IFERROR(INDEX((std_profil2_prt),MATCH($H16,Prt,0)),"") -> 0 | AJ16: =IFERROR(INDEX((std_profil_prt),MATCH($H16,Prt,0)),"") -> 0 | AK16: =IFERROR(INDEX((std_siku_prt),MATCH($H16,Prt,0)),"") -> 0 | AL16: =IFERROR(INDEX((std_screw_prt),MATCH($H16,Prt,0)),"") -> 0 | AN16: =IFERROR(INDEX((std_rel_prt),MATCH($H16,Prt,0)),"") -> 0 | AO16: =IFERROR(INDEX((std_engsel_prt),MATCH($H16,Prt,0)),"") -> 0 | AP16: =IFERROR(INDEX((std_anodizev_proses),MATCH($I16,pk,0)),"") | AQ16: =IFERROR(INDEX((std_anodizev2_proses),MATCH($I16,pk,0)),"") | AR16: =IFERROR(INDEX((std_anodizeh_proses),MATCH($I16,pk,0)),"") | AS16: =IFERROR(INDEX((std_anodize_per_ukuran),MATCH($H16,Prt,0)),"") -> 0 | AT16: =IF($AS16=edging7,L16,IF($AS16=edging8,L16,IF($AS16=edging9,L16,IF($AS16=Hand1,J15,IF($AS16=Hand2,L15,IF($AS16=hand3,"diisi manual",IF($AS16=hand4,"diisi manual",IF($AS16=hand5,"diisi manual",IF($AS16=mled02,J16,IF($AS16=mprf1,J16,IF($AS16=mlis1,J16,""))))))))))) | AU16: =IF($AS16="","",Q16*BR16) -> 0 | AW16: =CONCATENATE(VLOOKUP($V16,tabtf,2,0),VLOOKUP($X16,tabtf,2,0)) -> 37 | AX16: =IF($B16="alu",(CONCATENATE(VLOOKUP($AD16,tabfr,2,0),VLOOKUP($AE16,tabfr,2,0),VLOOKUP($AF16,tabfr,2,0),VLOOKUP($AG16,tabfr,2,0))),(CONCATENATE(VLOOKUP($AD16,tabte,2,0),VLOOKUP($AE16,tabte,2,0),VLOOKUP($AF16,tabte,2,0),VLOOKUP($AG16,tabte,2,0)))) -> 3233 | AY16: =IFERROR(VLOOKUP(AW16,descf,2,0),"") -> Aica_1mk_Polos | AZ16: =IF($B16="alu",(VLOOKUP(AX16,descfr,2,0)),(VLOOKUP(AX16,desce,2,0))) -> Melanor_1sisi_pjg | BA16: =IF($R16=0,CONCATENATE(0,")"," ",$H16," ",$J16),CONCATENATE(VLOOKUP(H16,tabprt,2,0),")",$H16,"_",AY16)) -> 414)Rangka back panel_Aica_1mk_Polos | BB16: =IF($B16="…",CONCATENATE(0,$E16,")"," ",$H16),IF($B16="kc",CONCATENATE(VLOOKUP(H16,tabprt,2,0),")",$H16," ",$R16," ",$S16,"mm"," ","-"," "," ",";"," ",$AZ16," ",$I16),IF($B16="alu",CONCATENATE(VLOOKUP(H16,tabprt,2,0),")",$H16," ",$R16," ",$S16,"mm"," ","-"," "," ",";"," ",$AZ16," ",$I16),CONCATENATE(VLOOKUP(H16,tabprt,2,0),")",$H16," ",$R16," ",$S16,"mm"," ","-"," ",$AY16," ",";"," ",$AZ16," ",$I16)))) -> 414)Rangka back panel Ply 18mm - Aica_1mk_Polos ; Melanor_1sisi_pjg | BD16: =IFERROR(INDEX((std_minifix_prt),MATCH($H16,Prt,0)),"") -> 0 | BE16: =IFERROR(INDEX((std_dowel_prt),MATCH($H16,Prt,0)),"") -> 0 | BF16: =IFERROR(INDEX((std_j_sikufr_prt),MATCH($H16,Prt,0)),"")*Q16 -> 0 | BG16: =IFERROR(INDEX((std_j_screwjf_prt),MATCH($H16,Prt,0)),"")*Q16 -> 0 | BH16: =IF($AM16=0,0,1)*Q16 -> 0 | BI16: =IF($AO16=0,0,IF(J16<=fp,2,(ROUNDUP(J16/fp,0))))*Q16 -> 0 | BJ16: =IF($AN16=0,0,1)*Q16 -> 0 | BK16: =(($J16+tol_p)*$Q16)/1000 -> 4.94 | BL16: =(($L16+tol_p)*$Q16)/1000 -> 0.19 | BM16: =IF(R16=0,0,((2*((J16+tol_p)+(L16+tol_p))*Q16)/1000)) -> 10.26 | BN16: =((J16*L16)/1000000)*Q16 -> 0.2673 | BO16: =CONCATENATE(R16,"_",S16) -> Ply_18 | BP16: =CONCATENATE(R16," ",S16," ",AY16) -> Ply 18 Aica_1mk_Polos | BQ16: =((J16*L16*Q16)/(2400*1200))+10% -> 0.1928125 | BR16: =IFERROR(INDEX((std_jml_anodize_per_uk),MATCH($H16,Prt,0)),"") -> 0 | BS16: =IF($BD16=0,0,IF($L16<150,2,((ROUNDUP($L16/fm,0)*2))))*$Q16 -> 0 | BT16: =IF($BE16=0,0,IF($L16<150,2,((ROUNDUP($L16/fd,0)*2))))*$Q16 -> 0 | BU16: =BF16*$Q16 -> 0 | BV16: =BG16*$Q16 -> 0 | BW16: =+((J16*L16)*Q16)/1000000 -> 0.2673 | BX16: =+((J16*L16*N16)*Q16)/1000000000 -> 0.00494505 | BY16: =IFERROR(INDEX((tbl_edg),MATCH($AD16,Edg,0)),"") | BZ16: =IFERROR(INDEX((tbl_edg),MATCH($AE16,Edg,0)),"") -> 0.5 | CA16: =IFERROR(INDEX((tbl_edg),MATCH($AF16,Edg,0)),"") | CB16: =IFERROR(INDEX((tbl_edg),MATCH($AG16,Edg,0)),"") | CC16: =IFERROR((J16-CA16-CB16),"") | CD16: =IFERROR((L16-BY16-BZ16),"") | CE16: =IFERROR((CONCATENATE(CC16," ","x"," ",CD16," ","x"," ",N16)),"") -> x x 18,5 | CF16: =IF(F16=1,(CONCATENATE(J16,";",L16,";",Q16,";",BP16,";",N16,";",H16,";","-1",";",AF16,";",CA16,";",AG16,";",CB16,";",AD16,";",BY16,";",AE16,";",BZ16))," ") -> 2430;55;2;Ply 18 Aica_1mk_Polos;18,5;Rangka back panel;-1; ;; ;; ;;Melanor;0,5
A18: =IFERROR(INDEX((ID),MATCH(H18,BARANG,0)),"…") -> … | B18: =IFERROR(INDEX((cprt),MATCH($H18,Prt,0)),"…") -> pintu | C18: prt | D18: =IFERROR(INDEX((KS),MATCH($H18,Prt,0)),"") -> KS | E18: A | F18: =IFERROR(INDEX((opt),MATCH($H18,Prt,0)),"") -> 0 | G18: =IFERROR(INDEX((no_ref),MATCH($H18,ref,0)),"...") -> ... | H18: Braket miring | J18: =+ROUNDDOWN(L14-N16-N16,0) -> 172 | K18: x | L18: 100 | M18: x | N18: =+(S18+W18+Y18) -> 18 | O18: =CONCATENATE(J18," ",K18," ",L18," ",M18," ",N18) -> 172 x 100 x 18 | P18: 4 | Q18: =+P18*Q14 -> 4 | R18: =IFERROR(INDEX((std_bhn_prt),MATCH($H18,Prt,0)),"") -> Ply | S18: =IFERROR(INDEX((std_Tbahan_prt),MATCH($H18,Prt,0)),"") -> 18 | T18: =INDEX((std_lapisan_luar_prt),MATCH($H18,Prt,0)) -> 0 | U18: =INDEX((std_lapisan_dalam_prt),MATCH($H18,Prt,0)) -> 0 | V18: =IFERROR(INDEX((tf),MATCH(T18,ctf,0)),"") -> Polos | W18: =IFERROR(INDEX((tebal_lapisan),MATCH($V18,tf,0)),"") -> 0 | X18: =IFERROR(INDEX((tf),MATCH(U18,ctf,0)),"") -> Polos | Y18: =IFERROR(INDEX((tebal_lapisan),MATCH($X18,tf,0)),"") -> 0 | Z18: =INDEX((std_edg_P1_prt),MATCH($H18,Prt,0)) -> 0 | AA18: =INDEX((std_edg_P2_prt),MATCH($H18,Prt,0)) -> 0 | AB18: =INDEX((std_edg_L1_prt),MATCH($H18,Prt,0)) -> 0 | AC18: =INDEX((std_edg_L2_prt),MATCH($H18,Prt,0)) -> 0 | AD18: =IF($B18="alu",(INDEX((Fr),MATCH(Z18,cfr,0))),INDEX((te),MATCH(Z18,cte,0))) | AE18: =IF($B18="alu",(INDEX((Fr),MATCH(AA18,cfr,0))),INDEX((te),MATCH(AA18,cte,0))) | AF18: =IF($B18="alu",(INDEX((Fr),MATCH(AB18,cfr,0))),INDEX((te),MATCH(AB18,cte,0))) | AG18: =IF($B18="alu",(INDEX((Fr),MATCH(AC18,cfr,0))),INDEX((te),MATCH(AC18,cte,0))) | AH18: =IFERROR(INDEX((std_profil3_prt),MATCH($H18,Prt,0)),"") -> 0 | AI18: =IFERROR(INDEX((std_profil2_prt),MATCH($H18,Prt,0)),"") -> 0 | AJ18: =IFERROR(INDEX((std_profil_prt),MATCH($H18,Prt,0)),"") -> 0 | AK18: =IFERROR(INDEX((std_siku_prt),MATCH($H18,Prt,0)),"") -> 0 | AL18: =IFERROR(INDEX((std_screw_prt),MATCH($H18,Prt,0)),"") -> 0 | AN18: =IFERROR(INDEX((std_rel_prt),MATCH($H18,Prt,0)),"") -> 0 | AO18: =IFERROR(INDEX((std_engsel_prt),MATCH($H18,Prt,0)),"") -> 0 | AP18: =IFERROR(INDEX((std_anodizev_proses),MATCH($I18,pk,0)),"") | AQ18: =IFERROR(INDEX((std_anodizev2_proses),MATCH($I18,pk,0)),"") | AR18: =IFERROR(INDEX((std_anodizeh_proses),MATCH($I18,pk,0)),"") | AS18: =IFERROR(INDEX((std_anodize_per_ukuran),MATCH($H18,Prt,0)),"") -> 0 | AT18: =IF($AS18=edging7,L18,IF($AS18=edging8,L18,IF($AS18=edging9,L18,IF($AS18=Hand1,J17,IF($AS18=Hand2,L17,IF($AS18=hand3,"diisi manual",IF($AS18=hand4,"diisi manual",IF($AS18=hand5,"diisi manual",IF($AS18=mled02,J18,IF($AS18=mprf1,J18,IF($AS18=mlis1,J18,""))))))))))) | AU18: =IF($AS18="","",Q18*BR18) -> 0 | AW18: =CONCATENATE(VLOOKUP($V18,tabtf,2,0),VLOOKUP($X18,tabtf,2,0)) -> 33 | AX18: =IF($B18="alu",(CONCATENATE(VLOOKUP($AD18,tabfr,2,0),VLOOKUP($AE18,tabfr,2,0),VLOOKUP($AF18,tabfr,2,0),VLOOKUP($AG18,tabfr,2,0))),(CONCATENATE(VLOOKUP($AD18,tabte,2,0),VLOOKUP($AE18,tabte,2,0),VLOOKUP($AF18,tabte,2,0),VLOOKUP($AG18,tabte,2,0)))) -> 3333 | AY18: =IFERROR(VLOOKUP(AW18,descf,2,0),"") -> Polos | AZ18: =IF($B18="alu",(VLOOKUP(AX18,descfr,2,0)),(VLOOKUP(AX18,desce,2,0))) -> - | BA18: =IF($R18=0,CONCATENATE(0,")"," ",$H18," ",$J18),CONCATENATE(VLOOKUP(H18,tabprt,2,0),")",$H18,"_",AY18)) -> 421)Braket miring_Polos | BB18: =IF($B18="…",CONCATENATE(0,$E18,")"," ",$H18),IF($B18="kc",CONCATENATE(VLOOKUP(H18,tabprt,2,0),")",$H18," ",$R18," ",$S18,"mm"," ","-"," "," ",";"," ",$AZ18," ",$I18),IF($B18="alu",CONCATENATE(VLOOKUP(H18,tabprt,2,0),")",$H18," ",$R18," ",$S18,"mm"," ","-"," "," ",";"," ",$AZ18," ",$I18),CONCATENATE(VLOOKUP(H18,tabprt,2,0),")",$H18," ",$R18," ",$S18,"mm"," ","-"," ",$AY18," ",";"," ",$AZ18," ",$I18)))) -> 421)Braket miring Ply 18mm - Polos ; - | BD18: =IFERROR(INDEX((std_minifix_prt),MATCH($H18,Prt,0)),"") -> 0 | BE18: =IFERROR(INDEX((std_dowel_prt),MATCH($H18,Prt,0)),"") -> 0 | BF18: =IFERROR(INDEX((std_j_sikufr_prt),MATCH($H18,Prt,0)),"")*Q18 -> 0 | BG18: =IFERROR(INDEX((std_j_screwjf_prt),MATCH($H18,Prt,0)),"")*Q18 -> 0 | BH18: =IF($AM18=0,0,1)*Q18 -> 0 | BI18: =IF($AO18=0,0,IF(J18<=fp,2,(ROUNDUP(J18/fp,0))))*Q18 -> 0 | BJ18: =IF($AN18=0,0,1)*Q18 -> 0 | BK18: =(($J18+tol_p)*$Q18)/1000 -> 0.848 | BL18: =(($L18+tol_p)*$Q18)/1000 -> 0.56 | BM18: =IF(R18=0,0,((2*((J18+tol_p)+(L18+tol_p))*Q18)/1000)) -> 2.816 | BN18: =((J18*L18)/1000000)*Q18 -> 0.0688 | BO18: =CONCATENATE(R18,"_",S18) -> Ply_18 | BP18: =CONCATENATE(R18," ",S18," ",AY18) -> Ply 18 Polos | BQ18: =((J18*L18*Q18)/(2400*1200))+10% -> 0.12388889 | BR18: =IFERROR(INDEX((std_jml_anodize_per_uk),MATCH($H18,Prt,0)),"") -> 0 | BS18: =IF($BD18=0,0,IF($L18<150,2,((ROUNDUP($L18/fm,0)*2))))*$Q18 -> 0 | BT18: =IF($BE18=0,0,IF($L18<150,2,((ROUNDUP($L18/fd,0)*2))))*$Q18 -> 0 | BU18: =BF18*$Q18 -> 0 | BV18: =BG18*$Q18 -> 0 | BW18: =+((J18*L18)*Q18)/1000000 -> 0.0688 | BX18: =+((J18*L18*N18)*Q18)/1000000000 -> 0.0012384 | BY18: =IFERROR(INDEX((tbl_edg),MATCH($AD18,Edg,0)),"") | BZ18: =IFERROR(INDEX((tbl_edg),MATCH($AE18,Edg,0)),"") | CA18: =IFERROR(INDEX((tbl_edg),MATCH($AF18,Edg,0)),"") | CB18: =IFERROR(INDEX((tbl_edg),MATCH($AG18,Edg,0)),"") | CC18: =IFERROR((J18-CA18-CB18),"") | CD18: =IFERROR((L18-BY18-BZ18),"") | CE18: =IFERROR((CONCATENATE(CC18," ","x"," ",CD18," ","x"," ",N18)),"") -> x x 18 | CF18: =IF(F18=1,(CONCATENATE(J18,";",L18,";",Q18,";",BP18,";",N18,";",H18,";","-1",";",AF18,";",CA18,";",AG18,";",CB18,";",AD18,";",BY18,";",AE18,";",BZ18))," ")
A21: =IFERROR(INDEX((ID),MATCH(H21,BARANG,0)),"…") -> … | B21: =IFERROR(INDEX((cprt),MATCH($H21,Prt,0)),"…") -> … | C21: Set_up | D21: =(INDEX(KS_Set,MATCH($H21,Set_prt,0))) -> [ks] | E21: A | F21: =IFERROR(INDEX((opt),MATCH($H21,Prt,0)),"") | G21: =IFERROR(INDEX((no_ref),MATCH($H21,ref,0)),"...") -> • | H21: Back Panel Rangka (rakit tukang) | J21: =1390+100 -> 1490 | K21: x | L21: 209 | M21: x | N21: 75 | O21: =CONCATENATE(J21," ",K21," ",L21," ",M21," ",N21) -> 1490 x 209 x 75 | Q21: 1 | AD21: =IF($B21="alu",(INDEX((Fr),MATCH(Z21,cfr,0))),INDEX((te),MATCH(Z21,cte,0))) | AE21: =IF($B21="alu",(INDEX((Fr),MATCH(AA21,cfr,0))),INDEX((te),MATCH(AA21,cte,0))) | AF21: =IF($B21="alu",(INDEX((Fr),MATCH(AB21,cfr,0))),INDEX((te),MATCH(AB21,cte,0))) | AG21: =IF($B21="alu",(INDEX((Fr),MATCH(AC21,cfr,0))),INDEX((te),MATCH(AC21,cte,0))) | AK21: =IFERROR(INDEX((std_siku_prt),MATCH($H21,Prt,0)),"") | AL21: =IFERROR(INDEX((std_screw_prt),MATCH($H21,Prt,0)),"") | AP21: =IFERROR(INDEX((std_anodizev_proses),MATCH($I21,pk,0)),"") | AQ21: =IFERROR(INDEX((std_anodizev2_proses),MATCH($I21,pk,0)),"") | AR21: =IFERROR(INDEX((std_anodizeh_proses),MATCH($I21,pk,0)),"") | AU21: =IF($AS21=0,"",Q21*BR21) | AX21: =IF($B21="alu",(CONCATENATE(VLOOKUP($AD21,tabfr,2,0),VLOOKUP($AE21,tabfr,2,0),VLOOKUP($AF21,tabfr,2,0),VLOOKUP($AG21,tabfr,2,0))),(CONCATENATE(VLOOKUP($AD21,tabte,2,0),VLOOKUP($AE21,tabte,2,0),VLOOKUP($AF21,tabte,2,0),VLOOKUP($AG21,tabte,2,0)))) -> 3333 | AY21: =IFERROR(VLOOKUP(AW21,descf,2,0),"") | AZ21: =IF($B21="alu",(VLOOKUP(AX21,descfr,2,0)),(VLOOKUP(AX21,desce,2,0))) -> - | BA21: =IF($R21=0,CONCATENATE(0,")"," ",$H21," ",$J21),CONCATENATE(VLOOKUP(H21,tabprt,2,0),")",$H21,"_",AY21)) -> 0) Back Panel Rangka (rakit tukang) 1490 | BB21: =IF($B21="…",CONCATENATE(0,$E21,")"," ",$H21),IF($B21="kc",CONCATENATE(VLOOKUP(H21,tabprt,2,0),")",$H21," ",$R21," ",$S21,"mm"," ","-"," "," ",";"," ",$AZ21," ",$I21),IF($B21="alu",CONCATENATE(VLOOKUP(H21,tabprt,2,0),")",$H21," ",$R21," ",$S21,"mm"," ","-"," "," ",";"," ",$AZ21," ",$I21),CONCATENATE(VLOOKUP(H21,tabprt,2,0),")",$H21," ",$R21," ",$S21,"mm"," ","-"," ",$AY21," ",";"," ",$AZ21," ",$I21)))) -> 0A) Back Panel Rangka (rakit tukang) | BD21: =IFERROR(INDEX((std_minifix_prt),MATCH($H21,Prt,0)),"") | BE21: =IFERROR(INDEX((std_dowel_prt),MATCH($H21,Prt,0)),"") | BH21: =IF($AM21=0,0,1)*Q21 -> 0 | BI21: =IF($AO21=0,0,IF(J21<=fp,2,(ROUNDUP(J21/fp,0))))*Q21 -> 0 | BJ21: =IF($AN21=0,0,1)*Q21 -> 0 | BK21: =(($J21+tol_p)*$Q21)/1000 -> 1.53 | BL21: =(($L21+tol_p)*$Q21)/1000 -> 0.249 | BM21: =IF(R21=0,0,((2*((J21+tol_p)+(L21+tol_p))*Q21)/1000)) -> 0 | BO21: =CONCATENATE(R21,"_",S21) -> _ | BP21: =CONCATENATE(R21," ",S21," ",AY21) | BQ21: =((J21*L21*Q21)/(2400*1200))+10% -> 0.20812847 | BR21: =IFERROR(INDEX((std_jml_anodize_per_uk),MATCH($H21,Prt,0)),"") | BS21: =IF($BD21=0,0,IF($L21<150,2,((ROUNDUP($L21/fm,0)*2))))*$Q21 -> 2 | BT21: =IF($BE21=0,0,IF($L21<150,2,((ROUNDUP($L21/fd,0)*2))))*$Q21 -> 4 | BW21: =+((J21*L21)*Q21)/1000000 -> 0.31141 | BX21: =+((J21*L21*N21)*Q21)/1000000000 -> 0.02335575 | BY21: =IFERROR(INDEX((tbl_edg),MATCH($AD21,Edg,0)),"") | BZ21: =IFERROR(INDEX((tbl_edg),MATCH($AE21,Edg,0)),"") | CA21: =IFERROR(INDEX((tbl_edg),MATCH($AF21,Edg,0)),"") | CB21: =IFERROR(INDEX((tbl_edg),MATCH($AG21,Edg,0)),"") | CC21: =IFERROR((J21-CA21-CB21),"") | CD21: =IFERROR((L21-BY21-BZ21),"") | CE21: =IFERROR((CONCATENATE(CC21," ","x"," ",CD21," ","x"," ",N21)),"") -> x x 75 | CF21: =IF(F21=1,(CONCATENATE(J21,";",L21,";",Q21,";",BP21,";",N21,";",H21,";","-1",";",AF21,";",CA21,";",AG21,";",CB21,";",AD21,";",BY21,";",AE21,";",BZ21))," ")
A22: =IFERROR(INDEX((ID),MATCH(H22,BARANG,0)),"…") -> … | B22: =IFERROR(INDEX((cprt),MATCH($H22,Prt,0)),"…") -> pintu | C22: prt | D22: =IFERROR(INDEX((KS),MATCH($H22,Prt,0)),"") -> KS | E22: A» | F22: =IFERROR(INDEX((opt),MATCH($H22,Prt,0)),"") -> 0 | G22: =IFERROR(INDEX((no_ref),MATCH($H22,ref,0)),"...") -> ... | H22: Back Panel Rangka | J22: =+J21 -> 1490 | K22: x | L22: =+L21 -> 209 | M22: x | N22: =+(S22+W22+Y22) -> 19 | O22: =CONCATENATE(J22," ",K22," ",L22," ",M22," ",N22) -> 1490 x 209 x 19 | P22: =IFERROR(INDEX((std_sub_prt),MATCH($H22,Prt,0)),"") -> 1 | Q22: =P22*Q21 -> 1 | R22: =IFERROR(INDEX((std_bhn_prt),MATCH($H22,Prt,0)),"") -> Ply | S22: =IFERROR(INDEX((std_Tbahan_prt),MATCH($H22,Prt,0)),"") -> 18 | T22: =INDEX((std_lapisan_luar_prt),MATCH($H22,Prt,0)) -> 1 | U22: =INDEX((std_lapisan_dalam_prt),MATCH($H22,Prt,0)) -> 0 | V22: =IFERROR(INDEX((tf),MATCH(T22,ctf,0)),"") -> WY_5216_D(V) | W22: =IFERROR(INDEX((tebal_lapisan),MATCH($V22,tf,0)),"") -> 1 | X22: =IFERROR(INDEX((tf),MATCH(U22,ctf,0)),"") -> Polos | Y22: =IFERROR(INDEX((tebal_lapisan),MATCH($X22,tf,0)),"") -> 0 | Z22: =INDEX((std_edg_P1_prt),MATCH($H22,Prt,0)) -> 1 | AA22: =INDEX((std_edg_P2_prt),MATCH($H22,Prt,0)) -> 1 | AB22: =INDEX((std_edg_L1_prt),MATCH($H22,Prt,0)) -> 1 | AC22: =INDEX((std_edg_L2_prt),MATCH($H22,Prt,0)) -> 1 | AD22: =IF($B22="alu",(INDEX((Fr),MATCH(Z22,cfr,0))),INDEX((te),MATCH(Z22,cte,0))) -> Edg_EAW_5216D1 | AE22: =IF($B22="alu",(INDEX((Fr),MATCH(AA22,cfr,0))),INDEX((te),MATCH(AA22,cte,0))) -> Edg_EAW_5216D1 | AF22: =IF($B22="alu",(INDEX((Fr),MATCH(AB22,cfr,0))),INDEX((te),MATCH(AB22,cte,0))) -> Edg_EAW_5216D1 | AG22: =IF($B22="alu",(INDEX((Fr),MATCH(AC22,cfr,0))),INDEX((te),MATCH(AC22,cte,0))) -> Edg_EAW_5216D1 | AH22: =IFERROR(INDEX((std_profil3_prt),MATCH($H22,Prt,0)),"") -> 0 | AI22: =IFERROR(INDEX((std_profil2_prt),MATCH($H22,Prt,0)),"") -> 0 | AJ22: =IFERROR(INDEX((std_profil_prt),MATCH($H22,Prt,0)),"") -> 0 | AK22: =IFERROR(INDEX((std_siku_prt),MATCH($H22,Prt,0)),"") -> 0 | AL22: =IFERROR(INDEX((std_screw_prt),MATCH($H22,Prt,0)),"") -> 0 | AN22: =IFERROR(INDEX((std_rel_prt),MATCH($H22,Prt,0)),"") -> 0 | AO22: =IFERROR(INDEX((std_engsel_prt),MATCH($H22,Prt,0)),"") -> 0 | AP22: =IFERROR(INDEX((std_anodizev_proses),MATCH($I22,pk,0)),"") | AQ22: =IFERROR(INDEX((std_anodizev2_proses),MATCH($I22,pk,0)),"") | AR22: =IFERROR(INDEX((std_anodizeh_proses),MATCH($I22,pk,0)),"") | AS22: =IFERROR(INDEX((std_anodize_per_ukuran),MATCH($H22,Prt,0)),"") -> 0 | AT22: =IF($AS22=edging7,L22,IF($AS22=edging8,L22,IF($AS22=edging9,L22,IF($AS22=Hand1,J21,IF($AS22=Hand2,L21,IF($AS22=hand3,"diisi manual",IF($AS22=hand4,"diisi manual",IF($AS22=hand5,"diisi manual",IF($AS22=mled02,J22,IF($AS22=mprf1,J22,IF($AS22=mlis1,J22,""))))))))))) | AU22: =IF($AS22="","",Q22*BR22) -> 0 | AW22: =CONCATENATE(VLOOKUP($V22,tabtf,2,0),VLOOKUP($X22,tabtf,2,0)) -> 13 | AX22: =IF($B22="alu",(CONCATENATE(VLOOKUP($AD22,tabfr,2,0),VLOOKUP($AE22,tabfr,2,0),VLOOKUP($AF22,tabfr,2,0),VLOOKUP($AG22,tabfr,2,0))),(CONCATENATE(VLOOKUP($AD22,tabte,2,0),VLOOKUP($AE22,tabte,2,0),VLOOKUP($AF22,tabte,2,0),VLOOKUP($AG22,tabte,2,0)))) -> 4444 | AY22: =IFERROR(VLOOKUP(AW22,descf,2,0),"") -> WY_5216_D(V)_1mk_Polos | AZ22: =IF($B22="alu",(VLOOKUP(AX22,descfr,2,0)),(VLOOKUP(AX22,desce,2,0))) -> Edg_EAW_5216D1_Keliling | BA22: =IF($R22=0,CONCATENATE(0,")"," ",$H22," ",$J22),CONCATENATE(VLOOKUP(H22,tabprt,2,0),")",$H22,"_",AY22)) -> 403)Back Panel Rangka_WY_5216_D(V)_1mk_Polos | BB22: =IF($B22="…",CONCATENATE(0,$E22,")"," ",$H22),IF($B22="kc",CONCATENATE(VLOOKUP(H22,tabprt,2,0),")",$H22," ",$R22," ",$S22,"mm"," ","-"," "," ",";"," ",$AZ22," ",$I22),IF($B22="alu",CONCATENATE(VLOOKUP(H22,tabprt,2,0),")",$H22," ",$R22," ",$S22,"mm"," ","-"," "," ",";"," ",$AZ22," ",$I22),CONCATENATE(VLOOKUP(H22,tabprt,2,0),")",$H22," ",$R22," ",$S22,"mm"," ","-"," ",$AY22," ",";"," ",$AZ22," ",$I22)))) -> 403)Back Panel Rangka Ply 18mm - WY_5216_D(V)_1mk_Polos ; Edg_EAW_5216D1_Keliling | BD22: =IFERROR(INDEX((std_minifix_prt),MATCH($H22,Prt,0)),"") -> 0 | BE22: =IFERROR(INDEX((std_dowel_prt),MATCH($H22,Prt,0)),"") -> 0 | BF22: =IFERROR(INDEX((std_j_sikufr_prt),MATCH($H22,Prt,0)),"")*Q22 -> 0 | BG22: =IFERROR(INDEX((std_j_screwjf_prt),MATCH($H22,Prt,0)),"")*Q22 -> 0 | BH22: =IF($AM22=0,0,1)*Q22 -> 0 | BI22: =IF($AO22=0,0,IF(J22<=fp,2,(ROUNDUP(J22/fp,0))))*Q22 -> 0 | BJ22: =IF($AN22=0,0,1)*Q22 -> 0 | BK22: =(($J22+tol_p)*$Q22)/1000 -> 1.53 | BL22: =(($L22+tol_p)*$Q22)/1000 -> 0.249 | BM22: =IF(R22=0,0,((2*((J22+tol_p)+(L22+tol_p))*Q22)/1000)) -> 3.558 | BN22: =((J22*L22)/1000000)*Q22 -> 0.31141 | BO22: =CONCATENATE(R22,"_",S22) -> Ply_18 | BP22: =CONCATENATE(R22," ",S22," ",AY22) -> Ply 18 WY_5216_D(V)_1mk_Polos | BQ22: =((J22*L22*Q22)/(2400*1200))+10% -> 0.20812847 | BR22: =IFERROR(INDEX((std_jml_anodize_per_uk),MATCH($H22,Prt,0)),"") -> 0 | BS22: =IF($BD22=0,0,IF($L22<150,2,((ROUNDUP($L22/fm,0)*2))))*$Q22 -> 0 | BT22: =IF($BE22=0,0,IF($L22<150,2,((ROUNDUP($L22/fd,0)*2))))*$Q22 -> 0 | BU22: =BF22*$Q22 -> 0 | BV22: =BG22*$Q22 -> 0 | BW22: =+((J22*L22)*Q22)/1000000 -> 0.31141 | BX22: =+((J22*L22*N22)*Q22)/1000000000 -> 0.00591679 | BY22: =IFERROR(INDEX((tbl_edg),MATCH($AD22,Edg,0)),"") | BZ22: =IFERROR(INDEX((tbl_edg),MATCH($AE22,Edg,0)),"") | CA22: =IFERROR(INDEX((tbl_edg),MATCH($AF22,Edg,0)),"") | CB22: =IFERROR(INDEX((tbl_edg),MATCH($AG22,Edg,0)),"") | CC22: =IFERROR((J22-CA22-CB22),"") | CD22: =IFERROR((L22-BY22-BZ22),"") | CE22: =IFERROR((CONCATENATE(CC22," ","x"," ",CD22," ","x"," ",N22)),"") -> x x 19 | CF22: =IF(F22=1,(CONCATENATE(J22,";",L22,";",Q22,";",BP22,";",N22,";",H22,";","-1",";",AF22,";",CA22,";",AG22,";",CB22,";",AD22,";",BY22,";",AE22,";",BZ22))," ")
A23: =IFERROR(INDEX((ID),MATCH(H23,BARANG,0)),"…") -> … | B23: =IFERROR(INDEX((cprt),MATCH($H23,Prt,0)),"…") -> pintu | C23: prt | D23: =IFERROR(INDEX((KS),MATCH($H23,Prt,0)),"") -> KS | E23: A | F23: =IFERROR(INDEX((opt),MATCH($H23,Prt,0)),"") -> 1 | G23: =IFERROR(INDEX((no_ref),MATCH($H23,ref,0)),"...") -> ... | H23: Rangka back panel | J23: 2430 | K23: x | L23: =ROUNDDOWN(N21-N22-tol,0) -> 55 | M23: x | N23: =+(S23+W23+Y23) -> 18.5 | O23: =CONCATENATE(J23," ",K23," ",L23," ",M23," ",N23) -> 2430 x 55 x 18,5 | P23: =ROUNDUP((((2*J21)+(4*L21))/2440),0) -> 2 | Q23: =+P23*Q21 -> 2 | R23: =IFERROR(INDEX((std_bhn_prt),MATCH($H23,Prt,0)),"") -> Ply | S23: =IFERROR(INDEX((std_Tbahan_prt),MATCH($H23,Prt,0)),"") -> 18 | T23: =INDEX((std_lapisan_luar_prt),MATCH($H23,Prt,0)) -> 0 | U23: =INDEX((std_lapisan_dalam_prt),MATCH($H23,Prt,0)) -> 22 | V23: =IFERROR(INDEX((tf),MATCH(T23,ctf,0)),"") -> Polos | W23: =IFERROR(INDEX((tebal_lapisan),MATCH($V23,tf,0)),"") -> 0 | X23: =IFERROR(INDEX((tf),MATCH(U23,ctf,0)),"") -> Aica | Y23: =IFERROR(INDEX((tebal_lapisan),MATCH($X23,tf,0)),"") -> 0.5 | Z23: =INDEX((std_edg_P1_prt),MATCH($H23,Prt,0)) -> 0 | AA23: =INDEX((std_edg_P2_prt),MATCH($H23,Prt,0)) -> 9 | AB23: =INDEX((std_edg_L1_prt),MATCH($H23,Prt,0)) -> 0 | AC23: =INDEX((std_edg_L2_prt),MATCH($H23,Prt,0)) -> 0 | AD23: =IF($B23="alu",(INDEX((Fr),MATCH(Z23,cfr,0))),INDEX((te),MATCH(Z23,cte,0))) | AE23: =IF($B23="alu",(INDEX((Fr),MATCH(AA23,cfr,0))),INDEX((te),MATCH(AA23,cte,0))) -> Melanor | AF23: =IF($B23="alu",(INDEX((Fr),MATCH(AB23,cfr,0))),INDEX((te),MATCH(AB23,cte,0))) | AG23: =IF($B23="alu",(INDEX((Fr),MATCH(AC23,cfr,0))),INDEX((te),MATCH(AC23,cte,0))) | AH23: =IFERROR(INDEX((std_profil3_prt),MATCH($H23,Prt,0)),"") -> 0 | AI23: =IFERROR(INDEX((std_profil2_prt),MATCH($H23,Prt,0)),"") -> 0 | AJ23: =IFERROR(INDEX((std_profil_prt),MATCH($H23,Prt,0)),"") -> 0 | AK23: =IFERROR(INDEX((std_siku_prt),MATCH($H23,Prt,0)),"") -> 0 | AL23: =IFERROR(INDEX((std_screw_prt),MATCH($H23,Prt,0)),"") -> 0 | AN23: =IFERROR(INDEX((std_rel_prt),MATCH($H23,Prt,0)),"") -> 0 | AO23: =IFERROR(INDEX((std_engsel_prt),MATCH($H23,Prt,0)),"") -> 0 | AP23: =IFERROR(INDEX((std_anodizev_proses),MATCH($I23,pk,0)),"") | AQ23: =IFERROR(INDEX((std_anodizev2_proses),MATCH($I23,pk,0)),"") | AR23: =IFERROR(INDEX((std_anodizeh_proses),MATCH($I23,pk,0)),"") | AS23: =IFERROR(INDEX((std_anodize_per_ukuran),MATCH($H23,Prt,0)),"") -> 0 | AT23: =IF($AS23=edging7,L23,IF($AS23=edging8,L23,IF($AS23=edging9,L23,IF($AS23=Hand1,J22,IF($AS23=Hand2,L22,IF($AS23=hand3,"diisi manual",IF($AS23=hand4,"diisi manual",IF($AS23=hand5,"diisi manual",IF($AS23=mled02,J23,IF($AS23=mprf1,J23,IF($AS23=mlis1,J23,""))))))))))) | AU23: =IF($AS23="","",Q23*BR23) -> 0 | AW23: =CONCATENATE(VLOOKUP($V23,tabtf,2,0),VLOOKUP($X23,tabtf,2,0)) -> 37 | AX23: =IF($B23="alu",(CONCATENATE(VLOOKUP($AD23,tabfr,2,0),VLOOKUP($AE23,tabfr,2,0),VLOOKUP($AF23,tabfr,2,0),VLOOKUP($AG23,tabfr,2,0))),(CONCATENATE(VLOOKUP($AD23,tabte,2,0),VLOOKUP($AE23,tabte,2,0),VLOOKUP($AF23,tabte,2,0),VLOOKUP($AG23,tabte,2,0)))) -> 3233 | AY23: =IFERROR(VLOOKUP(AW23,descf,2,0),"") -> Aica_1mk_Polos | AZ23: =IF($B23="alu",(VLOOKUP(AX23,descfr,2,0)),(VLOOKUP(AX23,desce,2,0))) -> Melanor_1sisi_pjg | BA23: =IF($R23=0,CONCATENATE(0,")"," ",$H23," ",$J23),CONCATENATE(VLOOKUP(H23,tabprt,2,0),")",$H23,"_",AY23)) -> 414)Rangka back panel_Aica_1mk_Polos | BB23: =IF($B23="…",CONCATENATE(0,$E23,")"," ",$H23),IF($B23="kc",CONCATENATE(VLOOKUP(H23,tabprt,2,0),")",$H23," ",$R23," ",$S23,"mm"," ","-"," "," ",";"," ",$AZ23," ",$I23),IF($B23="alu",CONCATENATE(VLOOKUP(H23,tabprt,2,0),")",$H23," ",$R23," ",$S23,"mm"," ","-"," "," ",";"," ",$AZ23," ",$I23),CONCATENATE(VLOOKUP(H23,tabprt,2,0),")",$H23," ",$R23," ",$S23,"mm"," ","-"," ",$AY23," ",";"," ",$AZ23," ",$I23)))) -> 414)Rangka back panel Ply 18mm - Aica_1mk_Polos ; Melanor_1sisi_pjg | BD23: =IFERROR(INDEX((std_minifix_prt),MATCH($H23,Prt,0)),"") -> 0 | BE23: =IFERROR(INDEX((std_dowel_prt),MATCH($H23,Prt,0)),"") -> 0 | BF23: =IFERROR(INDEX((std_j_sikufr_prt),MATCH($H23,Prt,0)),"")*Q23 -> 0 | BG23: =IFERROR(INDEX((std_j_screwjf_prt),MATCH($H23,Prt,0)),"")*Q23 -> 0 | BH23: =IF($AM23=0,0,1)*Q23 -> 0 | BI23: =IF($AO23=0,0,IF(J23<=fp,2,(ROUNDUP(J23/fp,0))))*Q23 -> 0 | BJ23: =IF($AN23=0,0,1)*Q23 -> 0 | BK23: =(($J23+tol_p)*$Q23)/1000 -> 4.94 | BL23: =(($L23+tol_p)*$Q23)/1000 -> 0.19 | BM23: =IF(R23=0,0,((2*((J23+tol_p)+(L23+tol_p))*Q23)/1000)) -> 10.26 | BN23: =((J23*L23)/1000000)*Q23 -> 0.2673 | BO23: =CONCATENATE(R23,"_",S23) -> Ply_18 | BP23: =CONCATENATE(R23," ",S23," ",AY23) -> Ply 18 Aica_1mk_Polos | BQ23: =((J23*L23*Q23)/(2400*1200))+10% -> 0.1928125 | BR23: =IFERROR(INDEX((std_jml_anodize_per_uk),MATCH($H23,Prt,0)),"") -> 0 | BS23: =IF($BD23=0,0,IF($L23<150,2,((ROUNDUP($L23/fm,0)*2))))*$Q23 -> 0 | BT23: =IF($BE23=0,0,IF($L23<150,2,((ROUNDUP($L23/fd,0)*2))))*$Q23 -> 0 | BU23: =BF23*$Q23 -> 0 | BV23: =BG23*$Q23 -> 0 | BW23: =+((J23*L23)*Q23)/1000000 -> 0.2673 | BX23: =+((J23*L23*N23)*Q23)/1000000000 -> 0.00494505 | BY23: =IFERROR(INDEX((tbl_edg),MATCH($AD23,Edg,0)),"") | BZ23: =IFERROR(INDEX((tbl_edg),MATCH($AE23,Edg,0)),"") -> 0.5 | CA23: =IFERROR(INDEX((tbl_edg),MATCH($AF23,Edg,0)),"") | CB23: =IFERROR(INDEX((tbl_edg),MATCH($AG23,Edg,0)),"") | CC23: =IFERROR((J23-CA23-CB23),"") | CD23: =IFERROR((L23-BY23-BZ23),"") | CE23: =IFERROR((CONCATENATE(CC23," ","x"," ",CD23," ","x"," ",N23)),"") -> x x 18,5 | CF23: =IF(F23=1,(CONCATENATE(J23,";",L23,";",Q23,";",BP23,";",N23,";",H23,";","-1",";",AF23,";",CA23,";",AG23,";",CB23,";",AD23,";",BY23,";",AE23,";",BZ23))," ") -> 2430;55;2;Ply 18 Aica_1mk_Polos;18,5;Rangka back panel;-1; ;; ;; ;;Melanor;0,5
